std::exception: More than one function with the name Foo. In %s and %s
