Testing subscription
FAIL

Caught: Problem(s) on subscription named 'X'. Connection IS alive.
First error:
exception 'InvalidOperationException' with message ''callback' called dynamically but is not __DynamicallyCallable' in :
Stack trace:
#0 {main}
