Fatal error: Uncaught exception 'BadMethodCallException' with message 'Await on a non-Awaitable' in %s:-1
Stack trace:
#0 %s(-1): foo()
#1 (): main()
#2 {main}
